<robot name="lexxhard">
  <link name="base_link" />

  <link name="left_wheel_link">
    <origin xyz="0 0 0" rpy="0 0 0" />
    <collision>
      <geometry>
        <cylinder radius="0.1016" length="0.5" />
      </geometry>
    </collision>
	<inertial>
		<origin xyz="0 0 0" rpy="0 0 0"/>
		<mass value="0.1"/>
		<inertia ixx="0.0001" ixy="0.0" ixz="0.0" iyy="0.0001" iyz="0.0" izz="0.0001"/>
	</inertial>
  </link>
  <joint name="left_wheel_joint" type="continuous">
    <parent link="base_link" />
    <child link="left_wheel_link" />
    <origin xyz="0 0.242 0.1016" rpy="1.57 0 0" />
    <axis xyz="0 1 0" />
    <limit effort="30" velocity="2.0" />
  </joint>
  <transmission name="left_wheel_trans">
    <type>transmission_interface/SimpleTransmission</type>
    <joint name="left_wheel_joint">
      <hardware_interface>EffortJointInterface</hardware_interface>
    </joint>
    <actuator name="left_wheel_motor">
      <hardware_interface>EffortJointInterface</hardware_interface>
      <mechanical_reduction>1</mechanical_reduction>
    </actuator>
  </transmission>
  <gazebo reference="left_wheel_link">
    <material>Gazebo/blue</material>
    <mu1 value="1.0"/>
    <mu2 value="1.0"/>
    <kp value="50000"/>
    <kd value="10"/>
  </gazebo>

  <link name="right_wheel_link">
    <origin xyz="0 0 0" rpy="0 0 0" />
    <collision>
      <geometry>
        <cylinder radius="0.1016" length="0.5" />
      </geometry>
    </collision>
	<inertial>
		<origin xyz="0 0 0" rpy="0 0 0"/>
		<mass value="0.1"/>
		<inertia ixx="0.0001" ixy="0.0" ixz="0.0" iyy="0.0001" iyz="0.0" izz="0.0001"/>
	</inertial>
  </link>
  <joint name="right_wheel_joint" type="continuous">
    <parent link="base_link" />
    <child link="right_wheel_link" />
    <origin xyz="0 -0.242 0.1016" rpy="1.57 0 0" />
    <axis xyz="0 1 0" />
    <limit effort="30" velocity="2.0" />
  </joint>
  <transmission name="right_wheel_trans">
    <type>transmission_interface/SimpleTransmission</type>
    <joint name="right_wheel_joint">
      <hardware_interface>EffortJointInterface</hardware_interface>
    </joint>
    <actuator name="right_wheel_motor">
      <hardware_interface>EffortJointInterface</hardware_interface>
      <mechanical_reduction>1</mechanical_reduction>
    </actuator>
  </transmission>
  <gazebo reference="left_wheel_link">
    <material>Gazebo/blue</material>
    <mu1 value="1.0"/>
    <mu2 value="1.0"/>
    <kp value="50000"/>
    <kd value="10"/>
  </gazebo>

	<gazebo>
		<plugin name="gazebo_ros_control" filename="libgazebo_ros_control.so">
			<robotNamespace>/</robotNamespace>
			<robotSimType>gazebo_ros_control/DefaultRobotHWSim</robotSimType>
			<legacyModeNS>true</legacyModeNS>
		</plugin>
	</gazebo>
</robot>
